
    <mujoco>
        <worldbody>
            <body name="torso" pos="0 0 0.350">
                <joint type="free"/>
                
                <geom name="torso_geom" type="box" size="0.05 0.05 0.05" material="robot_mat" mass="1"/>
                <geom name="head_geom" type="box" pos="0.03 0 0.06" size="0.03 0.03 0.03" rgba="1 1 1 0.8"/>
                
                <body name="left_leg" pos="0 0.06 0">
                    <joint name="hip_left" type="hinge" axis="0 1 0" damping="0.5" range="-100 100"/>
                    <geom type="capsule" fromto="0 0 0 0 0 -0.20" size="0.015" material="leg_mat"/>
                </body>
                
                <body name="right_leg" pos="0 -0.06 0">
                    <joint name="hip_right" type="hinge" axis="0 1 0" damping="0.5" range="-100 100"/>
                    <geom type="capsule" fromto="0 0 0 0 0 -0.20" size="0.015" material="leg_mat"/>
                </body>
            </body>
        </worldbody>
        
        <actuator>
            <motor joint="hip_left" gear="12" ctrllimited="true" ctrlrange="-1.0 1.0"/>
            <motor joint="hip_right" gear="12" ctrllimited="true" ctrlrange="-1.0 1.0"/>
        </actuator>
    </mujoco>
    